Workbook

Sheet Read.Me
G1: 5/3/1 Worksheet | K1: v3.0F | N1: Created by Pazienxa/diregna
A2: IMPORTANT: Only Modify the Boxes Highlighted in Grey
A4: Progress Tracker
A5: The Progress Tracker is 100% synced with your latest workout numbers. Just enter the number of reps done and the estimated 1RM will be automatically graphed and logged. It requires absolutely no work on your part to maintain. Even if you miss a week, the graph and tracker will be adjusted to correctly reflect this! Furthermore, your highest 1RM to date is always displayed on top of the sheet and of course, is done automatically for you. The only thing that you need to do is enter the number of reps done in the main worksheet!
A7: Stall Adjustment
A8: What really sets this 5/3/1 Worksheet apart from the every other weekly workout sheet is the Stall Adjustment. As much as we all want never ending progress, there comes a time when we have to readjust or lower the weight. In the past, this can only be done by readjusting your entire workout logs, erasing your past progress, and what if you have to reset more than once?
A9: This is what the Stall Adjustment is for. Not only will you be able to choose which exercise to reset, but also by how much. This is all done without adjusting the numbers from previous weeks or cycles. Furthermore, all of the weights in successive weeks will be properly adjusted to reflect the amount. You can reset as many times as necessary and everything will always be correctly adjusted. This includes the Progress Tracker! To use this feature, simply type any words or letter into the Stall Box next to the appropriate exercise and enter the amount of weight to back off. Your weights for the NEXT cycle will be appropriately adjusted. Weights for the current cycle will remain unchanged.
A10: Of course, nobody ever wants to use this feature ;)
A12: Rep Goals
A13: Explaination of Rep Goals - In week 1, the rep goal is calculated by adding 5lbs to your working 1RM. If you achieve the rep goal, your estimated 1RM will be at least 5lbs more than your working 1RM In week 2, the rep goal will be generated by adding 5lbs to your previous week's (week 1) estimated 1RM and the same concept works for week 3 if you get the rep goal. - If you are unable to get the number of reps recommended but the estimated 1RM is still greater than your current working 1RM, the following week's rep goal will still be generated by adding 5lbs onto your estimated 1RM. - However, if the estimated 1RM is lower than your current working 1RM at any given week, the rep goal for next week will be calculated such that you will beat your current working 1RM by 5lbs or more.
A15: For Example: Say my current working 1RM is 365 for squat. For week 1, I need to get 5+ for 310. The calculator also tells me that in order to beat my working 1RM of 365 by 5lbs, I will need to get at least 7 reps of 310 which will put me at an estimated 370. If I do get 7 reps, I will have to do 330x6=385 in week 2 to beat my max of 370 because if I only get 330x5, that is still an estimated max of 370. But say I wasn't feeling all that great and only went for the minimum number of 5 reps, that puts my estimated 1RM at 350, which is lower than my current working 1RM of 365. Therefore in week 2, the calculator will again add 5lbs to my current working 1RM of 365 and calculate the rep goal. In this scenario it will be 330x5 which gives an estimated 1RM of 370.
A17: For 3/5/1 Powerlifting, the rep goals are only in effect for weeks 1 and 3. Week 3's rep goals are calculated based on week 1's estimated 1RM
A19: As the weights get higher, it may become necessary to adjust the +5lbs to a higher amount to get a more accurate estimate. You may notice that the rep goal for the next week may give the same 1RM or even a lower 1RM. This is when you should modify the rep goal feature in the Start-Options page.
... A30: This spreadsheet is intended for personal use only and is in no way affliated with Jim Wendler. It is not intended to teach you the program or training methodologies. Please purchase his 5/3/1 Books if you have not done so already.
C31: =HYPERLINK("http://store.jimwendler.com/SearchResults.asp?Cat=1477","Buy 5/3/1") -> Buy 5/3/1
A32: The worksheet is protected by password and is not intended to be modified or changed without my direct consent or approval. The raw version will only be released to serious programmers for debugging, code refactoring, or development of future versions.
A34: Contact Me: You can reach me by the way of Private Messaging Pazienxa on Bodybuilding.com/forums or diregna on Reddit.

Sheet Start-Options
A1: 531 Start/Options
C3: Weight | D3: Reps | E3: 1RM | F3: 0.9 | I3: Multi Estimator
B4: Military | C4: 55 | D4: 1 | E4: =IF(D4="","",MROUND((C4*36)/(37-D4),B38)) -> 55 | F4: =IF(D4="","",MROUND(E4*0.9,5)) -> 50 | H4: Weight | I4: Reps | J4: 1RM
B5: Deadlift | C5: 90 | D5: 10 | E5: =IF(D5="","",MROUND((C5*36)/(37-D5),B38)) -> 120 | F5: =IF(D5="","",MROUND(E5*0.9,5)) -> 110 | J5: =IF(OR(I5="",H5=""),"",MROUND((36*H5)/(37-I5),5))
B6: Bench | C6: 75 | D6: 1 | E6: =IF(D6="","",MROUND((C6*36)/(37-D6),B38)) -> 75 | F6: =IF(D6="","",MROUND(E6*0.9,5)) -> 70 | I6: =IF(OR(H6="",J6=""),"",ROUND(37-(36*H6/J6),0))
B7: Squat | C7: 80 | D7: 5 | E7: =IF(D7="","",MROUND((C7*36)/(37-D7),B38)) -> 90 | F7: =IF(D7="","",MROUND(E7*0.9,5)) -> 80 | H7: =IF(OR(I7="",J7=""),"",MROUND(J7/(36/(37-I7)),5))
B8: Note: Information only needs to be entered once. Your training maxes will be automatically updated in each cycle.
B9: Accessory
B10: Day 1
B11: Pull Ups | C11: 90 | D11: 8 | E11: =IF(D11="","",MROUND((C11*36)/(37-D11),$B$38)) -> 112.5 | F11: =IF(D11="","",MROUND(E11*0.9,5)) -> 100
B12: Barbell Row | C12: 42.5 | D12: 10 | E12: =IF(D12="","",MROUND((C12*36)/(37-D12),$B$38)) -> 57.5 | F12: =IF(D12="","",MROUND(E12*0.9,5)) -> 50
B13: Dips | C13: 90 | D13: 8 | E13: =IF(D13="","",MROUND((C13*36)/(37-D13),$B$38)) -> 112.5 | F13: =IF(D13="","",MROUND(E13*0.9,5)) -> 100
B14: BB Curl | C14: 25 | D14: 5 | E14: =IF(D14="","",MROUND((C14*36)/(37-D14),$B$38)) -> 27.5 | F14: =IF(D14="","",MROUND(E14*0.9,5)) -> 25
B15: Barbell Rear Delt Row | C15: 30 | D15: 10 | E15: =IF(D15="","",MROUND((C15*36)/(37-D15),$B$38)) -> 40 | F15: =IF(D15="","",MROUND(E15*0.9,5)) -> 35
B16: Lateral Raise | C16: 10 | D16: 12 | E16: =IF(D16="","",MROUND((C16*36)/(37-D16),$B$38)) -> 15 | F16: =IF(D16="","",MROUND(E16*0.9,5)) -> 15 | G16: LBS
B17: Day 2
B18: RDL | C18: 50 | D18: 8 | E18: =IF(D18="","",MROUND((C18*36)/(37-D18),$B$38)) -> 62.5 | F18: =IF(D18="","",MROUND(E18*0.9,5)) -> 55
B19: Stiff Leg Deadlift | C19: 30 | D19: 10 | E19: =IF(D19="","",MROUND((C19*36)/(37-D19),$B$38)) -> 40 | F19: =IF(D19="","",MROUND(E19*0.9,5)) -> 35
B20: Hanging Leg Raise | C20: 90 | D20: 8 | E20: =IF(D20="","",MROUND((C20*36)/(37-D20),$B$38)) -> 112.5 | F20: =IF(D20="","",MROUND(E20*0.9,5)) -> 100
B21: Day 3
B22: Chin Ups | C22: 90 | D22: 8 | E22: =IF(D22="","",MROUND((C22*36)/(37-D22),$B$38)) -> 112.5 | F22: =IF(D22="","",MROUND(E22*0.9,5)) -> 100
B23: Incline Bench | C23: 45 | D23: 10 | E23: =IF(D23="","",MROUND((C23*36)/(37-D23),$B$38)) -> 60 | F23: =IF(D23="","",MROUND(E23*0.9,5)) -> 55
B24: Hammer Curl | C24: 30 | D24: 10 | E24: =IF(D24="","",MROUND((C24*36)/(37-D24),$B$38)) -> 40 | F24: =IF(D24="","",MROUND(E24*0.9,5)) -> 35
B25: Barbell Overhead Triceps Extension | C25: 10 | D25: 12 | E25: =IF(D25="","",MROUND((C25*36)/(37-D25),$B$38)) -> 15 | F25: =IF(D25="","",MROUND(E25*0.9,5)) -> 15
B26: Day 4
B27: Front Squat | C27: 30 | D27: 10 | E27: =IF(D27="","",MROUND((C27*36)/(37-D27),$B$38)) -> 40 | F27: =IF(D27="","",MROUND(E27*0.9,5)) -> 35
B28: Good Mornings | C28: 10 | D28: 12 | E28: =IF(D28="","",MROUND((C28*36)/(37-D28),$B$38)) -> 15 | F28: =IF(D28="","",MROUND(E28*0.9,5)) -> 15
B29: Barbell Hip Thrust | C29: 10 | D29: 12 | E29: =IF(D29="","",MROUND((C29*36)/(37-D29),$B$38)) -> 15 | F29: =IF(D29="","",MROUND(E29*0.9,5)) -> 15
B31: Increment/Cycle | E31: Rep Goal Increment | P31: =in -> #NAME?
B32: =B4 -> Military | C32: 2,5 | E32: =B4 -> Military | F32: 2.5 | H32: 5/3/1 Program
B33: =B5 -> Deadlift | C33: 5 | E33: =B5 -> Deadlift | F33: 2.5 | H33: 3/5/1 Powerlifters | L33: 2.5
B34: =B6 -> Bench | C34: 2,5 | E34: =B6 -> Bench | F34: 2.5 | H34: Progress Tracker 531
B35: =B7 -> Squat | C35: 5 | E35: =B7 -> Squat | F35: 2.5 | H35: Progress Tracker 351
E36: Accessory | F36: 2.5 | H36: Accessory Planner | L36: 18.5 | M36: =MROUND(L15,2) -> #ERROR! | O36: 20 | P36: =LCM(O36) -> 20
B37: Rounding | H37: 531 Beginner | L37: =L36+$L$33 -> 21 | O37: =O36+$L$33 -> 22.5 | P37: =LCM(O37) -> 22
B38: 2.5 | L38: =L37+$L$33 -> 23.5 | O38: =O37+$L$33 -> 25 | P38: =LCM(O38) -> 25
L39: =L38+$L$33 -> 26 | O39: =O38+$L$33 -> 27.5 | P39: =LCM(O39) -> 27
L40: =L39+$L$33 -> 28.5 | O40: =O39+$L$33 -> 30 | P40: =LCM(O40) -> 30
A41: It is strongly recommended that you do not modify any information on this page AFTER you have started your cycle.In addition, you are encouraged to lock the spreadsheet to prevent accidental deletion of formulaes. | L41: =L40+$L$33 -> 31 | O41: =O40+$L$33 -> 32.5 | P41: =LCM(O41) -> 32
L42: =L41+$L$33 -> 33.5 | O42: =O41+$L$33 -> 35 | P42: =LCM(O42) -> 35
...

Sheet 531
J1: 5/3/1 Calculator | P1: v3.0F
I2: Vikt | J2: 72.5 | K2: ='Kopia av Sheet1'!E10 -> 1 | L2: 20 | M2: kg
A3: 1RM Calculator | D3: Rep Goal Calculator | I3: Barbell | J3: 20 | K3: ='Kopia av Sheet1'!E11 -> 0 | L3: 15 | M3: kg | P3: Weight Calculator | V3: Start/Options
A4: Weight | B4: Reps | C4: 1RM | D4: Weight | E4: 1RM | F4: Rep | I4: Sida | J4: ='Kopia av Sheet1'!H14 -> 26.25 | K4: ='Kopia av Sheet1'!E12 -> 0 | L4: 10 | M4: kg | P4: 1RM | Q4: Reps | R4: Weight | V4: Progress Tracker
A5: 120 | B5: 3 | C5: =IF(OR(B5="",A5=""),"",MROUND((36*A5)/(37-B5),'Start-Options'!B38)) -> 127.5 | D5: 42.5 | E5: 50 | F5: =IF(OR(D5="",E5=""),"",ROUND(37-(36*D5/E5),0)) -> 6 | K5: ='Kopia av Sheet1'!E13 -> 1 | L5: 5 | M5: kg | R5: =IF(OR(Q5="",P5=""),"",MROUND(P5/(36/(37-Q5)),'Start-Options'!B38)) | V5: Accessory Planner
H6: Joker= 5 reps av +5 procent av tredje setet, öka med 5 procent till failure | K6: ='Kopia av Sheet1'!E14 -> 0 | L6: 2.5 | M6: kg
F7: FSL =3-5 sets av 5-8 reps av första setet | K7: ='Kopia av Sheet1'!E15 -> 1 | L7: 1.25 | M7: kg
L10: Cycle 1
B11: Week 1 3x5 | J11: Week 2 3x3 | Q11: Week 3 5/3/1 | V11: Week 4 Deload
B12: Weight | C12: Rep Goal | D12: 1RM Goal | E12: Reps Done | F12: 1RM | I12: Weight | J12: Rep Goal | K12: 1RM Goal | L12: Reps Done | M12: 1RM | P12: Weight | Q12: Rep Goal | R12: 1RM Goal | S12: Reps Done | T12: 1RM | W12: Weight | Y12: Cycle 1 1RM
B13: =IF('Start-Options'!D4="","",MROUND('Start-Options'!F4*0.65,'Start-Options'!B38)) -> 32.5 | I13: =IF('Start-Options'!D4="","",MROUND('Start-Options'!F4*0.7,'Start-Options'!B38)) -> 35 | P13: =IF('Start-Options'!D4="","",MROUND('Start-Options'!F4*0.75,'Start-Options'!B38)) -> 37.5 | W13: =IF('Start-Options'!D4="","",MROUND('Start-Options'!F4*0.4,'Start-Options'!B38)) -> 20 | Y13: ='Start-Options'!B4 -> Military | Z13: ='Start-Options'!F4 -> 50
A14: ='Start-Options'!B4 -> Military | B14: =IF('Start-Options'!D4="","",MROUND('Start-Options'!F4*0.75,'Start-Options'!B38)) -> 37.5 | H14: ='Start-Options'!B4 -> Military | I14: =IF('Start-Options'!D4="","",MROUND('Start-Options'!F4*0.8,'Start-Options'!B38)) -> 40 | O14: ='Start-Options'!B4 -> Military | P14: =IF('Start-Options'!D4="","",MROUND('Start-Options'!F4*0.85,'Start-Options'!B38)) -> 42.5 | V14: ='Start-Options'!B4 -> Military | W14: =IF('Start-Options'!D4="","",MROUND('Start-Options'!F4*0.5,'Start-Options'!B38)) -> 25 | Y14: ='Start-Options'!B5 -> Deadlift | Z14: ='Start-Options'!F5 -> 110
B15: =IF('Start-Options'!D4="","",MROUND('Start-Options'!F4*0.85,'Start-Options'!B38)) -> 42.5 | C15: =IF('Start-Options'!D4="","",ROUND((37-36*B15/('Start-Options'!F4+'Start-Options'!F32)),0)) -> 8 | D15: =IF('Start-Options'!D4="","",MROUND(B15*36/(37-C15),'Start-Options'!B38)) -> 52.5 | E15: 8 | F15: =IF(E15="","",MROUND(36*B15/(37-E15),'Start-Options'!B38)) -> 52.5 | I15: =IF('Start-Options'!D4="","",MROUND('Start-Options'!F4*0.9,'Start-Options'!B38)) -> 45 | J15: =IF(F15="","",IF(F15<'Start-Options'!F4,ROUND((37-36*I15/('Start-Options'!F4+'Start-Options'!F32)),0),ROUND((37-36*I15/(F15+'Start-Options'!F32)),0))) -> 8 | K15: =IF(J15="","",MROUND(I15*36/(37-J15),'Start-Options'!B38)) -> 55 | M15: =IF(L15="","",MROUND(36*I15/(37-L15),'Start-Options'!B38)) | P15: =IF('Start-Options'!D4="","",MROUND('Start-Options'!F4*0.95,'Start-Options'!B38)) -> 47.5 | Q15: =IF(M15="","",IF(M15<'Start-Options'!F4,ROUND((37-36*P15/('Start-Options'!F4+'Start-Options'!F32)),0),ROUND((37-36*P15/(M15+'Start-Options'!F32)),0))) | R15: =IF(Q15="","",MROUND(P15*36/(37-Q15),'Start-Options'!B38)) | T15: =IF(S15="","",MROUND(36*P15/(37-S15),'Start-Options'!B38)) | W15: =IF('Start-Options'!D4="","",MROUND('Start-Options'!F4*0.6,'Start-Options'!B38)) -> 30 | Y15: ='Start-Options'!B6 -> Bench | Z15: ='Start-Options'!F6 -> 70
B16: =IF('Start-Options'!D5="","",MROUND('Start-Options'!F5*0.65,'Start-Options'!B38)) -> 72.5 | I16: =IF('Start-Options'!D5="","",MROUND('Start-Options'!F5*0.7,'Start-Options'!B38)) -> 77.5 | P16: =IF('Start-Options'!D5="","",MROUND('Start-Options'!F5*0.75,'Start-Options'!B38)) -> 82.5 | W16: =IF('Start-Options'!D5="","",MROUND('Start-Options'!F5*0.4,'Start-Options'!B38)) -> 45 | Y16: ='Start-Options'!B7 -> Squat | Z16: ='Start-Options'!F7 -> 80
A17: ='Start-Options'!B5 -> Deadlift | B17: =IF('Start-Options'!D5="","",MROUND('Start-Options'!F5*0.75,'Start-Options'!B38)) -> 82.5 | H17: ='Start-Options'!B5 -> Deadlift | I17: =IF('Start-Options'!D5="","",MROUND('Start-Options'!F5*0.8,'Start-Options'!B38)) -> 87.5 | O17: ='Start-Options'!B5 -> Deadlift | P17: =IF('Start-Options'!D5="","",MROUND('Start-Options'!F5*0.85,'Start-Options'!B38)) -> 92.5 | V17: ='Start-Options'!B5 -> Deadlift | W17: =IF('Start-Options'!D5="","",MROUND('Start-Options'!F5*0.5,'Start-Options'!B38)) -> 55
B18: =IF('Start-Options'!D5="","",MROUND('Start-Options'!F5*0.85,'Start-Options'!B38)) -> 92.5 | C18: =IF('Start-Options'!D5="","",ROUND((37-36*B18/('Start-Options'!F5+'Start-Options'!F33)),0)) -> 7 | D18: =IF('Start-Options'!D5="","",MROUND(B18*36/(37-C18),'Start-Options'!B38)) -> 110 | E18: 7 | F18: =IF(E18="","",MROUND(36*B18/(37-E18),'Start-Options'!B38)) -> 110 | I18: =IF('Start-Options'!D5="","",MROUND('Start-Options'!F5*0.9,'Start-Options'!B38)) -> 100 | J18: =IF(F18="","",IF(F18<'Start-Options'!F5,ROUND((37-36*I18/('Start-Options'!F5+'Start-Options'!F33)),0),ROUND((37-36*I18/(F18+'Start-Options'!F33)),0))) -> 5 | K18: =IF(J18="","",MROUND(I18*36/(37-J18),'Start-Options'!B38)) -> 112.5 | M18: =IF(L18="","",MROUND(36*I18/(37-L18),'Start-Options'!B38)) | P18: =IF('Start-Options'!D5="","",MROUND('Start-Options'!F5*0.95,'Start-Options'!B38)) -> 105 | Q18: =IF(M18="","",IF(M18<'Start-Options'!F5,ROUND((37-36*P18/('Start-Options'!F5+'Start-Options'!F33)),0),ROUND((37-36*P18/(M18+'Start-Options'!F33)),0))) | R18: =IF(Q18="","",MROUND(P18*36/(37-Q18),'Start-Options'!B38)) | T18: =IF(S18="","",MROUND(36*P18/(37-S18),'Start-Options'!B38)) | W18: =IF('Start-Options'!D5="","",MROUND('Start-Options'!F5*0.6,'Start-Options'!B38)) -> 65 | Y18: Warm-up Calc
B19: =IF('Start-Options'!D6="","",MROUND('Start-Options'!F6*0.65,'Start-Options'!B38)) -> 45 | I19: =IF('Start-Options'!D6="","",MROUND('Start-Options'!F6*0.7,'Start-Options'!B38)) -> 50 | P19: =IF('Start-Options'!D6="","",MROUND('Start-Options'!F6*0.75,'Start-Options'!B38)) -> 52.5 | W19: =IF('Start-Options'!D6="","",MROUND('Start-Options'!F6*0.4,'Start-Options'!B38)) -> 27.5 | Y19: Top Set | Z19: 92.75
A20: ='Start-Options'!B6 -> Bench | B20: =IF('Start-Options'!D6="","",MROUND('Start-Options'!F6*0.75,'Start-Options'!B38)) -> 52.5 | H20: ='Start-Options'!B6 -> Bench | I20: =IF('Start-Options'!D6="","",MROUND('Start-Options'!F6*0.8,'Start-Options'!B38)) -> 55 | O20: ='Start-Options'!B6 -> Bench | P20: =IF('Start-Options'!D6="","",MROUND('Start-Options'!F6*0.85,'Start-Options'!B38)) -> 60 | V20: ='Start-Options'!B6 -> Bench | W20: =IF('Start-Options'!D6="","",MROUND('Start-Options'!F6*0.5,'Start-Options'!B38)) -> 35 | Y20: 40%x5 | Z20: =IF(Z19="","",MROUND(Z19*0.4,'Start-Options'!$B$38)) -> 37.5
B21: =IF('Start-Options'!D6="","",MROUND('Start-Options'!F6*0.85,'Start-Options'!B38)) -> 60 | C21: =IF('Start-Options'!D6="","",ROUND((37-36*B21/('Start-Options'!F6+'Start-Options'!F34)),0)) -> 7 | D21: =IF('Start-Options'!D6="","",MROUND(B21*36/(37-C21),'Start-Options'!B38)) -> 72.5 | F21: =IF(E21="","",MROUND(36*B21/(37-E21),'Start-Options'!B38)) | I21: =IF('Start-Options'!D6="","",MROUND('Start-Options'!F6*0.9,'Start-Options'!B38)) -> 62.5 | J21: =IF(F21="","",IF(F21<'Start-Options'!F6,ROUND((37-36*I21/('Start-Options'!F6+'Start-Options'!F34)),0),ROUND((37-36*I21/(F21+'Start-Options'!F34)),0))) | K21: =IF(J21="","",MROUND(I21*36/(37-J21),'Start-Options'!B38)) | M21: =IF(L21="","",MROUND(36*I21/(37-L21),'Start-Options'!B38)) | P21: =IF('Start-Options'!D6="","",MROUND('Start-Options'!F6*0.95,'Start-Options'!B38)) -> 67.5 | Q21: =IF(M21="","",IF(M21<'Start-Options'!F6,ROUND((37-36*P21/('Start-Options'!F6+'Start-Options'!F34)),0),ROUND((37-36*P21/(M21+'Start-Options'!F34)),0))) | R21: =IF(Q21="","",MROUND(P21*36/(37-Q21),'Start-Options'!B38)) | T21: =IF(S21="","",MROUND(36*P21/(37-S21),'Start-Options'!B38)) | W21: =IF('Start-Options'!D6="","",MROUND('Start-Options'!F6*0.6,'Start-Options'!B38)) -> 42.5 | Y21: 50%x5 | Z21: =IF(Z19="","",MROUND(Z19*0.5,'Start-Options'!$B$38)) -> 47.5
B22: =IF('Start-Options'!D7="","",MROUND('Start-Options'!F7*0.65,'Start-Options'!B38)) -> 52.5 | I22: =IF('Start-Options'!D7="","",MROUND('Start-Options'!F7*0.7,'Start-Options'!B38)) -> 55 | P22: =IF('Start-Options'!D7="","",MROUND('Start-Options'!F7*0.75,'Start-Options'!B38)) -> 60 | W22: =IF('Start-Options'!D7="","",MROUND('Start-Options'!F7*0.4,'Start-Options'!B38)) -> 32.5 | Y22: 60%x3 | Z22: =IF(Z19="","",MROUND(Z19*0.6,'Start-Options'!$B$38)) -> 55
A23: ='Start-Options'!B7 -> Squat | B23: =IF('Start-Options'!D7="","",MROUND('Start-Options'!F7*0.75,'Start-Options'!B38)) -> 60 | H23: ='Start-Options'!B7 -> Squat | I23: =IF('Start-Options'!D7="","",MROUND('Start-Options'!F7*0.8,'Start-Options'!B38)) -> 65 | O23: ='Start-Options'!B7 -> Squat | P23: =IF('Start-Options'!D7="","",MROUND('Start-Options'!F7*0.85,'Start-Options'!B38)) -> 67.5 | V23: ='Start-Options'!B7 -> Squat | W23: =IF('Start-Options'!D7="","",MROUND('Start-Options'!F7*0.5,'Start-Options'!B38)) -> 40
B24: =IF('Start-Options'!D7="","",MROUND('Start-Options'!F7*0.85,'Start-Options'!B38)) -> 67.5 | C24: =IF('Start-Options'!D7="","",ROUND((37-36*B24/('Start-Options'!F7+'Start-Options'!F35)),0)) -> 8 | D24: =IF('Start-Options'!D7="","",MROUND(B24*36/(37-C24),'Start-Options'!B38)) -> 85 | F24: =IF(E24="","",MROUND(36*B24/(37-E24),'Start-Options'!B38)) | I24: =IF('Start-Options'!D7="","",MROUND('Start-Options'!F7*0.9,'Start-Options'!B38)) -> 72.5 | J24: =IF(F24="","",IF(F24<'Start-Options'!F7,ROUND((37-36*I24/('Start-Options'!F7+'Start-Options'!F35)),0),ROUND((37-36*I24/(F24+'Start-Options'!F35)),0))) | K24: =IF(J24="","",MROUND(I24*36/(37-J24),'Start-Options'!B38)) | M24: =IF(L24="","",MROUND(36*I24/(37-L24),'Start-Options'!B38)) | P24: =IF('Start-Options'!D7="","",MROUND('Start-Options'!F7*0.95,'Start-Options'!B38)) -> 75 | Q24: =IF(M24="","",IF(M24<'Start-Options'!F7,ROUND((37-36*P24/('Start-Options'!F7+'Start-Options'!F35)),0),ROUND((37-36*P24/(M24+'Start-Options'!F35)),0))) | R24: =IF(Q24="","",MROUND(P24*36/(37-Q24),'Start-Options'!B38)) | T24: =IF(S24="","",MROUND(36*P24/(37-S24),'Start-Options'!B38)) | W24: =IF('Start-Options'!D7="","",MROUND('Start-Options'!F7*0.6,'Start-Options'!B38)) -> 47.5
L26: Cycle 2
C27: Week 5 3x5 | J27: Week 6 3x3 | Q27: Week 7 5/3/1 | V27: Week 8 Deload
B28: Weight | C28: Rep Goal | D28: 1RM Goal | E28: Reps Done | F28: 1RM | I28: Weight | J28: Rep Goal | K28: 1RM Goal | L28: Reps Done | M28: 1RM | P28: Weight | Q28: Rep Goal | R28: 1RM Goal | S28: Reps Done | T28: 1RM | W28: Weight | Y28: Cycle 2 1RM | AB28: Stall | AC28: Backoff Amount
B29: =IF(Z29="","",MROUND(Z29*0.65,'Start-Options'!B38)) -> 35 | I29: =IF(Z29="","",MROUND(Z29*0.7,'Start-Options'!B38)) -> 37.5 | P29: =IF(Z29="","",MROUND(Z29*0.75,'Start-Options'!B38)) -> 40 | W29: =IF(Z29="","",MROUND(Z29*0.4,'Start-Options'!B38)) -> 20 | Y29: ='Start-Options'!B4 -> Military | Z29: =IF('Start-Options'!F4="","",'Start-Options'!F4+'Start-Options'!C32) -> 52.5
A30: ='Start-Options'!B4 -> Military | B30: =IF(Z29="","",MROUND(Z29*0.75,'Start-Options'!B38)) -> 40 | H30: ='Start-Options'!B4 -> Military | I30: =IF(Z29="","",MROUND(Z29*0.8,'Start-Options'!B38)) -> 42.5 | O30: ='Start-Options'!B4 -> Military | P30: =IF(Z29="","",MROUND(Z29*0.85,'Start-Options'!B38)) -> 45 | V30: ='Start-Options'!B4 -> Military | W30: =IF(Z29="","",MROUND(Z29*0.5,'Start-Options'!B38)) -> 27.5 | Y30: ='Start-Options'!B5 -> Deadlift | Z30: =IF('Start-Options'!F5="","",'Start-Options'!F5+'Start-Options'!C33) -> 115
B31: =IF(Z29="","",MROUND(Z29*0.85,'Start-Options'!B38)) -> 45 | C31: =IF(Z29="","",ROUND((37-36*B31/(Z29+'Start-Options'!F32)),0)) -> 8 | D31: =IF(Z29="","",MROUND(B31*36/(37-C31),'Start-Options'!B38)) -> 55 | F31: =IF(E31="","",MROUND(36*B31/(37-E31),'Start-Options'!B38)) | I31: =IF(Z29="","",MROUND(Z29*0.9,'Start-Options'!B38)) -> 47.5 | J31: =IF(F31="","",IF(F31<Z29,ROUND((37-36*I31/(Z29+'Start-Options'!F32)),0),ROUND((37-36*I31/(F31+'Start-Options'!F32)),0))) | K31: =IF(J31="","",MROUND(I31*36/(37-J31),'Start-Options'!B38)) | M31: =IF(L31="","",MROUND(36*I31/(37-L31),'Start-Options'!B38)) | P31: =IF(Z29="","",MROUND(Z29*0.95,'Start-Options'!B38)) -> 50 | Q31: =IF(M31="","",IF(M31<Z29,ROUND((37-36*P31/(Z29+'Start-Options'!F32)),0),ROUND((37-36*P31/(M31+'Start-Options'!F32)),0))) | R31: =IF(Q31="","",MROUND(P31*36/(37-Q31),'Start-Options'!B38)) | T31: =IF(S31="","",MROUND(36*P31/(37-S31),'Start-Options'!B38)) | W31: =IF(Z29="","",MROUND(Z29*0.6,'Start-Options'!B38)) -> 32.5 | Y31: ='Start-Options'!B6 -> Bench | Z31: =IF('Start-Options'!F6="","",'Start-Options'!F6+'Start-Options'!C32) -> 72.5
B32: =IF(Z30="","",MROUND(Z30*0.65,'Start-Options'!B38)) -> 75 | I32: =IF(Z30="","",MROUND(Z30*0.7,'Start-Options'!B38)) -> 80 | P32: =IF(Z30="","",MROUND(Z30*0.75,'Start-Options'!B38)) -> 87.5 | W32: =IF(Z30="","",MROUND(Z30*0.4,'Start-Options'!B38)) -> 45 | Y32: ='Start-Options'!B7 -> Squat | Z32: =IF('Start-Options'!F7="","",'Start-Options'!F7+'Start-Options'!C35) -> 85
A33: ='Start-Options'!B5 -> Deadlift | B33: =IF(Z30="","",MROUND(Z30*0.75,'Start-Options'!B38)) -> 87.5 | H33: ='Start-Options'!B5 -> Deadlift | I33: =IF(Z30="","",MROUND(Z30*0.8,'Start-Options'!B38)) -> 92.5 | O33: ='Start-Options'!B5 -> Deadlift | P33: =IF(Z30="","",MROUND(Z30*0.85,'Start-Options'!B38)) -> 97.5 | V33: ='Start-Options'!B5 -> Deadlift | W33: =IF(Z30="","",MROUND(Z30*0.5,'Start-Options'!B38)) -> 57.5
B34: =IF(Z30="","",MROUND(Z30*0.85,'Start-Options'!B38)) -> 97.5 | C34: =IF(Z30="","",ROUND((37-36*B34/(Z30+'Start-Options'!F33)),0)) -> 7 | D34: =IF(Z30="","",MROUND(B34*36/(37-C34),'Start-Options'!B38)) -> 117.5 | F34: =IF(E34="","",MROUND(36*B34/(37-E34),'Start-Options'!B38)) | I34: =IF(Z30="","",MROUND(Z30*0.9,'Start-Options'!B38)) -> 102.5 | J34: =IF(F34="","",IF(F34<Z30,ROUND((37-36*I34/(Z30+'Start-Options'!F33)),0),ROUND((37-36*I34/(F34+'Start-Options'!F33)),0))) | K34: =IF(J34="","",MROUND(I34*36/(37-J34),'Start-Options'!B38)) | M34: =IF(L34="","",MROUND(36*I34/(37-L34),'Start-Options'!B38)) | P34: =IF(Z30="","",MROUND(Z30*0.95,'Start-Options'!B38)) -> 110 | Q34: =IF(M34="","",IF(M34<Z30,ROUND((37-36*P34/(Z30+'Start-Options'!F33)),0),ROUND((37-36*P34/(M34+'Start-Options'!F33)),0))) | R34: =IF(Q34="","",MROUND(P34*36/(37-Q34),'Start-Options'!B38)) | T34: =IF(S34="","",MROUND(36*P34/(37-S34),'Start-Options'!B38)) | W34: =IF(Z30="","",MROUND(Z30*0.6,'Start-Options'!B38)) -> 70 | Y34: Warm-up Calc
B35: =IF(Z31="","",MROUND(Z31*0.65,'Start-Options'!B38)) -> 47.5 | I35: =IF(Z31="","",MROUND(Z31*0.7,'Start-Options'!B38)) -> 50 | P35: =IF(Z31="","",MROUND(Z31*0.75,'Start-Options'!B38)) -> 55 | W35: =IF(Z31="","",MROUND(Z31*0.4,'Start-Options'!B38)) -> 30 | Y35: Top Set | Z35: 80
A36: ='Start-Options'!B6 -> Bench | B36: =IF(Z31="","",MROUND(Z31*0.75,'Start-Options'!B38)) -> 55 | H36: ='Start-Options'!B6 -> Bench | I36: =IF(Z31="","",MROUND(Z31*0.8,'Start-Options'!B38)) -> 57.5 | O36: ='Start-Options'!B6 -> Bench | P36: =IF(Z31="","",MROUND(Z31*0.85,'Start-Options'!B38)) -> 62.5 | V36: ='Start-Options'!B6 -> Bench | W36: =IF(Z31="","",MROUND(Z31*0.5,'Start-Options'!B38)) -> 37.5 | Y36: 40%x5 | Z36: =IF(Z35="","",MROUND(Z35*0.4,'Start-Options'!$B$38)) -> 32.5
B37: =IF(Z31="","",MROUND(Z31*0.85,'Start-Options'!B38)) -> 62.5 | C37: =IF(Z31="","",ROUND((37-36*B37/(Z31+'Start-Options'!F34)),0)) -> 7 | D37: =IF(Z31="","",MROUND(B37*36/(37-C37),'Start-Options'!B38)) -> 75 | F37: =IF(E37="","",MROUND(36*B37/(37-E37),'Start-Options'!B38)) | I37: =IF(Z31="","",MROUND(Z31*0.9,'Start-Options'!B38)) -> 65 | J37: =IF(F37="","",IF(F37<Z31,ROUND((37-36*I37/(Z31+'Start-Options'!F34)),0),ROUND((37-36*I37/(F37+'Start-Options'!F34)),0))) | K37: =IF(J37="","",MROUND(I37*36/(37-J37),'Start-Options'!B38)) | M37: =IF(L37="","",MROUND(36*I37/(37-L37),'Start-Options'!B38)) | P37: =IF(Z31="","",MROUND(Z31*0.95,'Start-Options'!B38)) -> 70 | Q37: =IF(M37="","",IF(M37<Z31,ROUND((37-36*P37/(Z31+'Start-Options'!F34)),0),ROUND((37-36*P37/(M37+'Start-Options'!F34)),0))) | R37: =IF(Q37="","",MROUND(P37*36/(37-Q37),'Start-Options'!B38)) | T37: =IF(S37="","",MROUND(36*P37/(37-S37),'Start-Options'!B38)) | W37: =IF(Z31="","",MROUND(Z31*0.6,'Start-Options'!B38)) -> 42.5 | Y37: 50%x5 | Z37: =IF(Z35="","",MROUND(Z35*0.5,'Start-Options'!$B$38)) -> 40
B38: =IF(Z32="","",MROUND(Z32*0.65,'Start-Options'!B38)) -> 55 | I38: =IF(Z32="","",MROUND(Z32*0.7,'Start-Options'!B38)) -> 60 | P38: =IF(Z32="","",MROUND(Z32*0.75,'Start-Options'!B38)) -> 65 | W38: =IF(Z32="","",MROUND(Z32*0.4,'Start-Options'!B38)) -> 35 | Y38: 60%x3 | Z38: =IF(Z35="","",MROUND(Z35*0.6,'Start-Options'!$B$38)) -> 47.5
A39: ='Start-Options'!B7 -> Squat | B39: =IF(Z32="","",MROUND(Z32*0.75,'Start-Options'!B38)) -> 65 | H39: ='Start-Options'!B7 -> Squat | I39: =IF(Z32="","",MROUND(Z32*0.8,'Start-Options'!B38)) -> 67.5 | O39: ='Start-Options'!B7 -> Squat | P39: =IF(Z32="","",MROUND(Z32*0.85,'Start-Options'!B38)) -> 72.5 | V39: ='Start-Options'!B7 -> Squat | W39: =IF(Z32="","",MROUND(Z32*0.5,'Start-Options'!B38)) -> 42.5
B40: =IF(Z32="","",MROUND(Z32*0.85,'Start-Options'!B38)) -> 72.5 | C40: =IF(Z32="","",ROUND((37-36*B40/(Z32+'Start-Options'!F35)),0)) -> 7 | D40: =IF(Z32="","",MROUND(B40*36/(37-C40),'Start-Options'!B38)) -> 87.5 | F40: =IF(E40="","",MROUND(36*B40/(37-E40),'Start-Options'!B38)) | I40: =IF(Z32="","",MROUND(Z32*0.9,'Start-Options'!B38)) -> 77.5 | J40: =IF(F40="","",IF(F40<Z32,ROUND((37-36*I40/(Z32+'Start-Options'!F35)),0),ROUND((37-36*I40/(F40+'Start-Options'!F35)),0))) | K40: =IF(J40="","",MROUND(I40*36/(37-J40),'Start-Options'!B38)) | M40: =IF(L40="","",MROUND(36*I40/(37-L40),'Start-Options'!B38)) | P40: =IF(Z32="","",MROUND(Z32*0.95,'Start-Options'!B38)) -> 80 | Q40: =IF(M40="","",IF(M40<Z32,ROUND((37-36*P40/(Z32+'Start-Options'!F35)),0),ROUND((37-36*P40/(M40+'Start-Options'!F35)),0))) | R40: =IF(Q40="","",MROUND(P40*36/(37-Q40),'Start-Options'!B38)) | T40: =IF(S40="","",MROUND(36*P40/(37-S40),'Start-Options'!B38)) | W40: =IF(Z32="","",MROUND(Z32*0.6,'Start-Options'!B38)) -> 50
L42: Cycle 3
C43: Week 9 3x5 | J43: Week 10 3x3 | Q43: Week 11 5/3/1 | V43: Week 12 Deload
B44: Weight | C44: Rep Goal | D44: 1RM Goal | E44: Reps Done | F44: 1RM | I44: Weight | J44: Rep Goal | K44: 1RM Goal | L44: Reps Done | M44: 1RM | P44: Weight | Q44: Rep Goal | R44: 1RM Goal | S44: Reps Done | T44: 1RM | W44: Weight | Y44: Cycle 3 1RM | AB44: Stall | AC44: Backoff Amount
...

Sheet  Accessory
I1: Assistance/Accessory Work Planner | P1: v3.0F
K3: 5/3/1 | L3: 5/3/1 Beginner | O3: 3/5/1 PL
I5: Cycle 1
A6: Week 1 | B6: Assistance | F6: Accessory | J6: Week 2 | K6: Assistance | O6: Accessory | S6: Assistance Template
B7: Exercise | C7: Weight | E7: Reps | F7: Exercise | G7: Set/Reps | H7: Weight | K7: Exercise | L7: Weight | N7: Reps | O7: Exercise | P7: Set/Reps | Q7: Weight | S7: Boring But Big
A8: Day 3 Status: | B8: =IF(S7="Accessory Only","",IF(S7="Boring But Big",'Start-Options'!$B$4,T38)) -> Military | C8: =IF(S7="Accessory Only","",IF(S7="Boring But Big",IF(U11="","",MROUND(T11*U11,'Start-Options'!$B$38)),IF(T34=531,MROUND(U38*0.5,'Start-Options'!$B$38),MROUND(U38*0.6,'Start-Options'!$B$38)))) -> 30 | D8: =T17 -> 25 | E8: =IF(S7="Accessory Only","",IF(S7="Boring But Big",10,IF(T34=531,10,8))) -> 10 | F8: Lats | G8: 10 | J8: Day 3 Status: | K8: =IF(S7="Accessory Only","",IF(S7="Boring But Big",'Start-Options'!$B$4,T38)) -> Military | L8: =IF(S7="Accessory Only","",IF(S7="Boring But Big",IF(V11="","",MROUND(T11*V11,'Start-Options'!$B$38)),IF(T34=531,MROUND(U38*0.6,'Start-Options'!$B$38),MROUND(U38*0.5,'Start-Options'!$B$38)))) -> 30 | N8: =IF(S7="Accessory Only","",IF(S7="Boring But Big",10,IF(T34=531,8,10))) -> 10 | O8: Lats | P8: 10 | Q8: 40
C9: =IF(S7="Accessory Only","",IF(S7="Boring But Big",IF(U11="","",MROUND(T11*U11,'Start-Options'!$B$38)),IF(T34=531,MROUND(U38*0.6,'Start-Options'!$B$38),MROUND(U38*0.7,'Start-Options'!$B$38)))) -> 30 | D9: =U17 -> 30 | E9: =IF(S7="Accessory Only","",IF(S7="Boring But Big",10,IF(T34=531,10,8))) -> 10 | F9: Lats | G9: 10 | L9: =IF(S7="Accessory Only","",IF(S7="Boring But Big",IF(V11="","",MROUND(T11*V11,'Start-Options'!$B$38)),IF(T34=531,MROUND(U38*0.7,'Start-Options'!$B$38),MROUND(U38*0.6,'Start-Options'!$B$38)))) -> 30 | N9: =IF(S7="Accessory Only","",IF(S7="Boring But Big",10,IF(T34=531,8,10))) -> 10 | O9: Lats | P9: 10 | Q9: 40 | S9: Boring But Big
C10: =IF(S7="Accessory Only","",IF(S7="Boring But Big",IF(U11="","",MROUND(T11*U11,'Start-Options'!$B$38)),IF(T34=531,MROUND(U38*0.7,'Start-Options'!$B$38),MROUND(U38*0.8,'Start-Options'!$B$38)))) -> 30 | D10: =V17 -> 35 | E10: =IF(S7="Accessory Only","",IF(S7="Boring But Big",10,IF(T34=531,10,6))) -> 10 | F10: Lats | G10: 10 | L10: =IF(S7="Accessory Only","",IF(S7="Boring But Big",IF(V11="","",MROUND(T11*V11,'Start-Options'!$B$38)),IF(T34=531,MROUND(U38*0.8,'Start-Options'!$B$38),MROUND(U38*0.7,'Start-Options'!$B$38)))) -> 30 | N10: =IF(S7="Accessory Only","",IF(S7="Boring But Big",10,IF(T34=531,6,10))) -> 10 | O10: Lats | P10: 10 | Q10: 40 | S10: 5x10 | T10: 1RM | U10: Wk1 | V10: Wk2 | W10: Wk3 | X10: Wk4
C11: =IF(S7="Boring But Big",IF(U11="","",MROUND(T11*U11,'Start-Options'!$B$38)),"") -> 30 | D11: =W17 -> 30 | E11: =IF(S7="Boring But Big",10,"") -> 10 | F11: Lats | G11: 10 | L11: =IF(S7="Boring But Big",IF(V11="","",MROUND(T11*V11,'Start-Options'!$B$38)),"") -> 30 | N11: =IF(S7="Boring But Big",10,"") -> 10 | O11: Lats | P11: 10 | Q11: 40 | S11: Military | T11: ='531'!Z13 -> 50 | U11: 0.6 | V11: 0.6 | W11: 0.6 | X11: 0.6
C12: =IF(S7="Boring But Big",IF(U11="","",MROUND(T11*U11,'Start-Options'!$B$38)),"") -> 30 | D12: =X17 -> 25 | E12: =IF(S7="Boring But Big",10,"") -> 10 | F12: Lats | G12: 10 | L12: =IF(S7="Boring But Big",IF(V11="","",MROUND(T11*V11,'Start-Options'!$B$38)),"") -> 30 | N12: =IF(S7="Boring But Big",10,"") -> 10 | O12: Lats | P12: 10 | Q12: 40 | S12: Deadlift | T12: ='531'!Z14 -> 110 | U12: 0.6 | V12: 0.6 | W12: 0.6 | X12: 0.6
A13: Day 4: Status: | B13: =IF(S7="Accessory Only","",IF(S7="Boring But Big",'Start-Options'!$B$5,T39)) -> Deadlift | C13: =IF(S7="Accessory Only","",IF(S7="Boring But Big",IF(U12="","",MROUND(T12*U12,'Start-Options'!$B$38)),IF(T34=531,MROUND(U39*0.5,'Start-Options'!$B$38),MROUND(U39*0.6,'Start-Options'!$B$38)))) -> 65 | D13: =T18 -> 55 | E13: =IF(S7="Accessory Only","",IF(S7="Boring But Big",10,IF(T34=531,10,8))) -> 10 | F13: Abs | G13: 10 | J13: Day 4: Status: | K13: =IF(S7="Accessory Only","",IF(S7="Boring But Big",'Start-Options'!$B$5,T39)) -> Deadlift | L13: =IF(S7="Accessory Only","",IF(S7="Boring But Big",IF(V12="","",MROUND(T12*V12,'Start-Options'!$B$38)),IF(T34=531,MROUND(U39*0.6,'Start-Options'!$B$38),MROUND(U39*0.5,'Start-Options'!$B$38)))) -> 65 | N13: =IF(S7="Accessory Only","",IF(S7="Boring But Big",10,IF(T34=531,8,10))) -> 10 | O13: Abs | P13: 10 | Q13: 55 | S13: Bench | T13: ='531'!Z15 -> 70 | U13: 0.6 | V13: 0.6 | W13: 0.6 | X13: 0.6
C14: =IF(S7="Accessory Only","",IF(S7="Boring But Big",IF(U12="","",MROUND(T12*U12,'Start-Options'!$B$38)),IF(T34=531,MROUND(U39*0.6,'Start-Options'!$B$38),MROUND(U39*0.7,'Start-Options'!$B$38)))) -> 65 | D14: =U18 -> 65 | E14: =IF(S7="Accessory Only","",IF(S7="Boring But Big",10,IF(T34=531,10,8))) -> 10 | F14: Abs | G14: 10 | L14: =IF(S7="Accessory Only","",IF(S7="Boring But Big",IF(V12="","",MROUND(T12*V12,'Start-Options'!$B$38)),IF(T34=531,MROUND(U39*0.7,'Start-Options'!$B$38),MROUND(U39*0.6,'Start-Options'!$B$38)))) -> 65 | N14: =IF(S7="Accessory Only","",IF(S7="Boring But Big",10,IF(T34=531,8,10))) -> 10 | O14: Abs | P14: 10 | S14: Squat | T14: ='531'!Z16 -> 80 | U14: 0.6 | V14: 0.6 | W14: 0.6 | X14: 0.6
C15: =IF(S7="Accessory Only","",IF(S7="Boring But Big",IF(U12="","",MROUND(T12*U12,'Start-Options'!$B$38)),IF(T34=531,MROUND(U39*0.7,'Start-Options'!$B$38),MROUND(U39*0.8,'Start-Options'!$B$38)))) -> 65 | D15: =V18 -> 75 | E15: =IF(S7="Accessory Only","",IF(S7="Boring But Big",10,IF(T34=531,10,6))) -> 10 | F15: Abs | G15: 10 | L15: =IF(S7="Accessory Only","",IF(S7="Boring But Big",IF(V12="","",MROUND(T12*V12,'Start-Options'!$B$38)),IF(T34=531,MROUND(U39*0.8,'Start-Options'!$B$38),MROUND(U39*0.7,'Start-Options'!$B$38)))) -> 65 | N15: =IF(S7="Accessory Only","",IF(S7="Boring But Big",10,IF(T34=531,6,10))) -> 10 | O15: Abs | P15: 10 | T15: 0.5 | U15: 0.6 | V15: 0.7 | W15: 0.6 | X15: 0.5
C16: =IF(S7="Boring But Big",IF(U12="","",MROUND(T12*U12,'Start-Options'!$B$38)),"") -> 65 | D16: =W18 -> 65 | E16: =IF(S7="Boring But Big",10,"") -> 10 | F16: Abs | G16: 10 | L16: =IF(S7="Boring But Big",IF(V12="","",MROUND(T12*V12,'Start-Options'!$B$38)),"") -> 65 | N16: =IF(S7="Boring But Big",10,"") -> 10 | O16: Abs | P16: 10 | S16: 5x10 | T16: set1 | U16: set2 | V16: set3 | W16: set4 | X16: set5
C17: =IF(S7="Boring But Big",IF(U12="","",MROUND(T12*U12,'Start-Options'!$B$38)),"") -> 65 | D17: =X18 -> 55 | E17: =IF(S7="Boring But Big",10,"") -> 10 | F17: Abs | G17: 10 | L17: =IF(S7="Boring But Big",IF(V12="","",MROUND(T12*V12,'Start-Options'!$B$38)),"") -> 65 | N17: =IF(S7="Boring But Big",10,"") -> 10 | O17: Abs | P17: 10 | S17: Military | T17: =Mround($T$11*T15,2.5) -> 25 | U17: =Mround($T$11*U15,2.5) -> 30 | V17: =Mround($T$11*V15,2.5) -> 35 | W17: =Mround($T$11*W15,2.5) -> 30 | X17: =Mround($T$11*X15,2.5) -> 25
A18: Day 1 Status: | B18: =IF(S7="Accessory Only","",IF(S7="Boring But Big",'Start-Options'!$B$6,T40)) -> Bench | C18: =IF(S7="Accessory Only","",IF(S7="Boring But Big",IF(U13="","",MROUND(T13*U13,'Start-Options'!$B$38)),IF(T34=531,MROUND(U40*0.5,'Start-Options'!$B$38),MROUND(U40*0.6,'Start-Options'!$B$38)))) -> 42.5 | D18: =T19 -> 35 | E18: =IF(S7="Accessory Only","",IF(S7="Boring But Big",10,IF(T34=531,10,8))) -> 10 | F18: Lats | G18: 10 | J18: Day 1 Status: | K18: =IF(S7="Accessory Only","",IF(S7="Boring But Big",'Start-Options'!$B$6,T40)) -> Bench | L18: =IF(S7="Accessory Only","",IF(S7="Boring But Big",IF(V13="","",MROUND(T13*V13,'Start-Options'!$B$38)),IF(T34=531,MROUND(U40*0.6,'Start-Options'!$B$38),MROUND(U40*0.5,'Start-Options'!$B$38)))) -> 42.5 | N18: =IF(S7="Accessory Only","",IF(S7="Boring But Big",10,IF(T34=531,8,10))) -> 10 | O18: Lats | P18: 10 | Q18: 40 | S18: Deadlift | T18: =mround($T$12*T15,5) -> 55 | U18: =mround($T$12*U15,5) -> 65 | V18: =mround($T$12*V15,5) -> 75 | W18: =mround($T$12*W15,5) -> 65 | X18: =mround($T$12*X15,5) -> 55
C19: =IF(S7="Accessory Only","",IF(S7="Boring But Big",IF(U13="","",MROUND(T13*U13,'Start-Options'!$B$38)),IF(T34=531,MROUND(U40*0.6,'Start-Options'!$B$38),MROUND(U40*0.7,'Start-Options'!$B$38)))) -> 42.5 | D19: =U19 -> 42.5 | E19: =IF(S7="Accessory Only","",IF(S7="Boring But Big",10,IF(T34=531,10,8))) -> 10 | F19: Lats | G19: 10 | L19: =IF(S7="Accessory Only","",IF(S7="Boring But Big",IF(V13="","",MROUND(T13*V13,'Start-Options'!$B$38)),IF(T34=531,MROUND(U40*0.7,'Start-Options'!$B$38),MROUND(U40*0.6,'Start-Options'!$B$38)))) -> 42.5 | N19: =IF(S7="Accessory Only","",IF(S7="Boring But Big",10,IF(T34=531,8,10))) -> 10 | O19: Lats | P19: 10 | Q19: 40 | S19: Bench | T19: =mround($T$13*T15,2.5) -> 35 | U19: =mround($T$13*U15,2.5) -> 42.5 | V19: =mround($T$13*V15,2.5) -> 50 | W19: =mround($T$13*W15,2.5) -> 42.5 | X19: =mround($T$13*X15,2.5) -> 35
C20: =IF(S7="Accessory Only","",IF(S7="Boring But Big",IF(U13="","",MROUND(T13*U13,'Start-Options'!$B$38)),IF(T34=531,MROUND(U40*0.7,'Start-Options'!$B$38),MROUND(U40*0.8,'Start-Options'!$B$38)))) -> 42.5 | D20: =V19 -> 50 | E20: =IF(S7="Accessory Only","",IF(S7="Boring But Big",10,IF(T34=531,10,6))) -> 10 | F20: Lats | G20: 10 | L20: =IF(S7="Accessory Only","",IF(S7="Boring But Big",IF(V13="","",MROUND(T13*V13,'Start-Options'!$B$38)),IF(T34=531,MROUND(U40*0.8,'Start-Options'!$B$38),MROUND(U40*0.7,'Start-Options'!$B$38)))) -> 42.5 | N20: =IF(S7="Accessory Only","",IF(S7="Boring But Big",10,IF(T34=531,6,10))) -> 10 | O20: Lats | P20: 10 | Q20: 40 | S20: Squat | T20: =mround($T$14*T15,5) -> 40 | U20: =mround($T$14*U15,5) -> 50 | V20: =mround($T$14*V15,5) -> 55 | W20: =mround($T$14*W15,5) -> 50 | X20: =mround($T$14*X15,5) -> 40
C21: =IF(S7="Boring But Big",IF(U13="","",MROUND(T13*U13,'Start-Options'!$B$38)),"") -> 42.5 | D21: =W19 -> 42.5 | E21: =IF(S7="Boring But Big",10,"") -> 10 | F21: Lats | G21: 10 | L21: =IF(S7="Boring But Big",IF(V13="","",MROUND(T13*V13,'Start-Options'!$B$38)),"") -> 42.5 | N21: =IF(S7="Boring But Big",10,"") -> 10 | O21: Lats | P21: 10 | Q21: 40
C22: =IF(S7="Boring But Big",IF(U13="","",MROUND(T13*U13,'Start-Options'!$B$38)),"") -> 42.5 | D22: =X19 -> 35 | E22: =IF(S7="Boring But Big",10,"") -> 10 | F22: Lats | G22: 10 | L22: =IF(S7="Boring But Big",IF(V13="","",MROUND(T13*V13,'Start-Options'!$B$38)),"") -> 42.5 | N22: =IF(S7="Boring But Big",10,"") -> 10 | O22: Lats | P22: 10 | Q22: 40
A23: Day 2 Status: | B23: =IF(S7="Accessory Only","",IF(S7="Boring But Big",'Start-Options'!$B$7,T41)) -> Squat | C23: =IF(S7="Accessory Only","",IF(S7="Boring But Big",IF(U14="","",MROUND(T14*U14,'Start-Options'!$B$38)),IF(T34=531,MROUND(U41*0.5,'Start-Options'!$B$38),MROUND(U41*0.6,'Start-Options'!$B$38)))) -> 47.5 | D23: =T20 -> 40 | E23: =IF(S7="Accessory Only","",IF(S7="Boring But Big",10,IF(T34=531,10,8))) -> 10 | F23: Abs | G23: 10 | J23: Day 2 Status: | K23: =IF(S7="Accessory Only","",IF(S7="Boring But Big",'Start-Options'!$B$7,T41)) -> Squat | L23: =IF(S7="Accessory Only","",IF(S7="Boring But Big",IF(V14="","",MROUND(T14*V14,'Start-Options'!$B$38)),IF(T34=531,MROUND(U41*0.6,'Start-Options'!$B$38),MROUND(U41*0.5,'Start-Options'!$B$38)))) -> 47.5 | N23: =IF(S7="Accessory Only","",IF(S7="Boring But Big",10,IF(T34=531,8,10))) -> 10 | O23: Abs | P23: 10 | Q23: 60
C24: =IF(S7="Accessory Only","",IF(S7="Boring But Big",IF(U14="","",MROUND(T14*U14,'Start-Options'!$B$38)),IF(T34=531,MROUND(U41*0.6,'Start-Options'!$B$38),MROUND(U41*0.7,'Start-Options'!$B$38)))) -> 47.5 | D24: =U20 -> 50 | E24: =IF(S7="Accessory Only","",IF(S7="Boring But Big",10,IF(T34=531,10,8))) -> 10 | F24: Abs | G24: 10 | L24: =IF(S7="Accessory Only","",IF(S7="Boring But Big",IF(V14="","",MROUND(T14*V14,'Start-Options'!$B$38)),IF(T34=531,MROUND(U41*0.7,'Start-Options'!$B$38),MROUND(U41*0.6,'Start-Options'!$B$38)))) -> 47.5 | N24: =IF(S7="Accessory Only","",IF(S7="Boring But Big",10,IF(T34=531,8,10))) -> 10 | O24: Abs | P24: 10
C25: =IF(S7="Accessory Only","",IF(S7="Boring But Big",IF(U14="","",MROUND(T14*U14,'Start-Options'!$B$38)),IF(T34=531,MROUND(U41*0.7,'Start-Options'!$B$38),MROUND(U41*0.8,'Start-Options'!$B$38)))) -> 47.5 | D25: =V20 -> 55 | E25: =IF(S7="Accessory Only","",IF(S7="Boring But Big",10,IF(T34=531,10,6))) -> 10 | F25: Abs | G25: 10 | L25: =IF(S7="Accessory Only","",IF(S7="Boring But Big",IF(V14="","",MROUND(T14*V14,'Start-Options'!$B$38)),IF(T34=531,MROUND(U41*0.8,'Start-Options'!$B$38),MROUND(U41*0.7,'Start-Options'!$B$38)))) -> 47.5 | N25: =IF(S7="Accessory Only","",IF(S7="Boring But Big",10,IF(T34=531,6,10))) -> 10 | O25: Abs | P25: 10
C26: =IF(S7="Boring But Big",IF(U14="","",MROUND(T14*U14,'Start-Options'!$B$38)),"") -> 47.5 | D26: =W20 -> 50 | E26: =IF(S7="Boring But Big",10,"") -> 10 | F26: Abs | G26: 10 | L26: =IF(S7="Boring But Big",IF(V14="","",MROUND(T14*V14,'Start-Options'!$B$38)),"") -> 47.5 | N26: =IF(S7="Boring But Big",10,"") -> 10 | O26: Abs | P26: 10
C27: =IF(S7="Boring But Big",IF(U14="","",MROUND(T14*U14,'Start-Options'!$B$38)),"") -> 47.5 | D27: =X20 -> 40 | E27: =IF(S7="Boring But Big",10,"") -> 10 | F27: Abs | G27: 10 | L27: =IF(S7="Boring But Big",IF(V14="","",MROUND(T14*V14,'Start-Options'!$B$38)),"") -> 47.5 | N27: =IF(S7="Boring But Big",10,"") -> 10 | O27: Abs | P27: 10
A29: Week 3 | B29: Assistance | F29: Accessory | J29: Week 4 | K29: Assistance | O29: Accessory
B30: Exercise | C30: Weight | E30: Reps | F30: Exercise | G30: Set/Reps | H30: Weight | K30: Exercise | L30: Weight | N30: Reps | O30: Exercise | P30: Set/Reps | Q30: Weight
A31: Day 3 Status: | B31: =IF(S7="Accessory Only","",IF(S7="Boring But Big",'Start-Options'!$B$4,T38)) -> Military | C31: =IF(S7="Accessory Only","",IF(S7="Boring But Big",IF(W11="","",MROUND(T11*W11,'Start-Options'!$B$38)),IF(T34=531,MROUND(U38*0.65,'Start-Options'!$B$38),MROUND(U38*0.65,'Start-Options'!$B$38)))) -> 30 | E31: =IF(S7="Accessory Only","",IF(S7="Boring But Big",10,5)) -> 10 | J31: Day 3 Status: | K31: =IF(S7="Accessory Only","",IF(S7="Boring But Big",'Start-Options'!$B$4,T38)) -> Military | L31: =IF(S7="Accessory Only","",IF(S7="Boring But Big",IF(X11="","",MROUND(T11*X11,'Start-Options'!$B$38)),MROUND(U38*0.4,'Start-Options'!$B$38))) -> 30 | N31: =IF(S7="Accessory Only","",IF(S7="Boring But Big",10,5)) -> 10
C32: =IF(S7="Accessory Only","",IF(S7="Boring But Big",IF(W11="","",MROUND(T11*W11,'Start-Options'!$B$38)),IF(T34=531,MROUND(U38*0.75,'Start-Options'!$B$38),MROUND(U38*0.75,'Start-Options'!$B$38)))) -> 30 | E32: =IF(S7="Accessory Only","",IF(S7="Boring But Big",10,5)) -> 10 | L32: =IF(S7="Accessory Only","",IF(S7="Boring But Big",IF(X11="","",MROUND(T11*X11,'Start-Options'!$B$38)),MROUND(U38*0.5,'Start-Options'!$B$38))) -> 30 | N32: =IF(S7="Accessory Only","",IF(S7="Boring But Big",10,5)) -> 10
C33: =IF(S7="Accessory Only","",IF(S7="Boring But Big",IF(W11="","",MROUND(T11*W11,'Start-Options'!$B$38)),IF(T34=531,MROUND(U38*0.85,'Start-Options'!$B$38),MROUND(U38*0.85,'Start-Options'!$B$38)))) -> 30 | E33: =IF(S7="Accessory Only","",IF(S7="Boring But Big",10,5)) -> 10 | L33: =IF(S7="Accessory Only","",IF(S7="Boring But Big",IF(X11="","",MROUND(T11*X11,'Start-Options'!$B$38)),MROUND(U38*0.6,'Start-Options'!$B$38))) -> 30 | N33: =IF(S7="Accessory Only","",IF(S7="Boring But Big",10,5)) -> 10 | S33: Simplest Strength Template
C34: =IF(S7="Boring But Big",IF(W11="","",MROUND(T11*W11,'Start-Options'!$B$38)),"") -> 30 | E34: =IF(S7="Boring But Big",10,"") -> 10 | L34: =IF(S7="Boring But Big",IF(X11="","",MROUND(T11*X11,'Start-Options'!$B$38)),"") -> 30 | N34: =IF(S7="Boring But Big",10,"") -> 10 | S34: 531 or 351? | T34: 531
C35: =IF(S7="Boring But Big",IF(W11="","",MROUND(T11*W11,'Start-Options'!$B$38)),"") -> 30 | E35: =IF(S7="Boring But Big",10,"") -> 10 | L35: =IF(S7="Boring But Big",IF(X11="","",MROUND(T11*X11,'Start-Options'!$B$38)),"") -> 30 | N35: =IF(S7="Boring But Big",10,"") -> 10
A36: Day 4: Status: | B36: =IF(S7="Accessory Only","",IF(S7="Boring But Big",'Start-Options'!$B$5,T39)) -> Deadlift | C36: =IF(S7="Accessory Only","",IF(S7="Boring But Big",IF(W12="","",MROUND(T12*W12,'Start-Options'!$B$38)),IF(T34=531,MROUND(U39*0.65,'Start-Options'!$B$38),MROUND(U39*0.65,'Start-Options'!$B$38)))) -> 65 | E36: =IF(S7="Accessory Only","",IF(S7="Boring But Big",10,5)) -> 10 | J36: Day 4: Status: | K36: =IF(S7="Accessory Only","",IF(S7="Boring But Big",'Start-Options'!$B$5,T39)) -> Deadlift | L36: =IF(S7="Accessory Only","",IF(S7="Boring But Big",IF(X12="","",MROUND(T12*X12,'Start-Options'!$B$38)),MROUND(U39*0.4,'Start-Options'!$B$38))) -> 65 | N36: =IF(S7="Accessory Only","",IF(S7="Boring But Big",10,5)) -> 10 | S36: Simplest Strength Template | W36: OH+B+Latwork
C37: =IF(S7="Accessory Only","",IF(S7="Boring But Big",IF(W12="","",MROUND(T12*W12,'Start-Options'!$B$38)),IF(T34=531,MROUND(U39*0.75,'Start-Options'!$B$38),MROUND(U39*0.75,'Start-Options'!$B$38)))) -> 65 | E37: =IF(S7="Accessory Only","",IF(S7="Boring But Big",10,5)) -> 10 | L37: =IF(S7="Accessory Only","",IF(S7="Boring But Big",IF(X12="","",MROUND(T12*X12,'Start-Options'!$B$38)),MROUND(U39*0.5,'Start-Options'!$B$38))) -> 65 | N37: =IF(S7="Accessory Only","",IF(S7="Boring But Big",10,5)) -> 10 | T37: Exercise | U37: 1RM | W37: D+Sq+Abs
C38: =IF(S7="Accessory Only","",IF(S7="Boring But Big",IF(W12="","",MROUND(T12*W12,'Start-Options'!$B$38)),IF(T34=531,MROUND(U39*0.85,'Start-Options'!$B$38),MROUND(U39*0.85,'Start-Options'!$B$38)))) -> 65 | E38: =IF(S7="Accessory Only","",IF(S7="Boring But Big",10,5)) -> 10 | L38: =IF(S7="Accessory Only","",IF(S7="Boring But Big",IF(X12="","",MROUND(T12*X12,'Start-Options'!$B$38)),MROUND(U39*0.6,'Start-Options'!$B$38))) -> 65 | N38: =IF(S7="Accessory Only","",IF(S7="Boring But Big",10,5)) -> 10 | S38: Day 1 | T38: Exercise 1 | U38: 100 | W38: B+OH+Lats
C39: =IF(S7="Boring But Big",IF(W12="","",MROUND(T12*W12,'Start-Options'!$B$38)),"") -> 65 | E39: =IF(S7="Boring But Big",10,"") -> 10 | L39: =IF(S7="Boring But Big",IF(X12="","",MROUND(T12*X12,'Start-Options'!$B$38)),"") -> 65 | N39: =IF(S7="Boring But Big",10,"") -> 10 | S39: Day 2 | T39: Exercise 2 | U39: 100 | W39: Sq+Dead+Abs
C40: =IF(S7="Boring But Big",IF(W12="","",MROUND(T12*W12,'Start-Options'!$B$38)),"") -> 65 | E40: =IF(S7="Boring But Big",10,"") -> 10 | L40: =IF(S7="Boring But Big",IF(X12="","",MROUND(T12*X12,'Start-Options'!$B$38)),"") -> 65 | N40: =IF(S7="Boring But Big",10,"") -> 10 | S40: Day 3 | T40: Exercise 3 | U40: 100
A41: Day 1 Status: | B41: =IF(S7="Accessory Only","",IF(S7="Boring But Big",'Start-Options'!$B$6,T40)) -> Bench | C41: =IF(S7="Accessory Only","",IF(S7="Boring But Big",IF(W13="","",MROUND(T13*W13,'Start-Options'!$B$38)),IF(T34=531,MROUND(U40*0.65,'Start-Options'!$B$38),MROUND(U40*0.65,'Start-Options'!$B$38)))) -> 42.5 | E41: =IF(S7="Accessory Only","",IF(S7="Boring But Big",10,5)) -> 10 | F41: lats var upptagen | G41: 5 | H41: 40 | J41: Day 1 Status: | K41: =IF(S7="Accessory Only","",IF(S7="Boring But Big",'Start-Options'!$B$6,T40)) -> Bench | L41: =IF(S7="Accessory Only","",IF(S7="Boring But Big",IF(X13="","",MROUND(T13*X13,'Start-Options'!$B$38)),MROUND(U40*0.4,'Start-Options'!$B$38))) -> 42.5 | N41: =IF(S7="Accessory Only","",IF(S7="Boring But Big",10,5)) -> 10 | S41: Day 4 | T41: Exercise 4 | U41: 100
C42: =IF(S7="Accessory Only","",IF(S7="Boring But Big",IF(W13="","",MROUND(T13*W13,'Start-Options'!$B$38)),IF(T34=531,MROUND(U40*0.75,'Start-Options'!$B$38),MROUND(U40*0.75,'Start-Options'!$B$38)))) -> 42.5 | E42: =IF(S7="Accessory Only","",IF(S7="Boring But Big",10,5)) -> 10 | L42: =IF(S7="Accessory Only","",IF(S7="Boring But Big",IF(X13="","",MROUND(T13*X13,'Start-Options'!$B$38)),MROUND(U40*0.5,'Start-Options'!$B$38))) -> 42.5 | N42: =IF(S7="Accessory Only","",IF(S7="Boring But Big",10,5)) -> 10
C43: =IF(S7="Accessory Only","",IF(S7="Boring But Big",IF(W13="","",MROUND(T13*W13,'Start-Options'!$B$38)),IF(T34=531,MROUND(U40*0.85,'Start-Options'!$B$38),MROUND(U40*0.85,'Start-Options'!$B$38)))) -> 42.5 | E43: =IF(S7="Accessory Only","",IF(S7="Boring But Big",10,5)) -> 10 | F43: abs | G43: 5 | H43: 55 | L43: =IF(S7="Accessory Only","",IF(S7="Boring But Big",IF(X13="","",MROUND(T13*X13,'Start-Options'!$B$38)),MROUND(U40*0.6,'Start-Options'!$B$38))) -> 42.5 | N43: =IF(S7="Accessory Only","",IF(S7="Boring But Big",10,5)) -> 10
...

Sheet Extra!
E1: https://www.youtube.com/watch?v=OMg8GlND-V4
E2: https://www.bodybuilding.com/exercises/lying-rear-delt-raise
A3: Barbell Hip Thrust | B3: https://www.youtube.com/watch?time_continue=70&v=Zp26q4BY5HE&feature=emb_title | E3: https://www.youtube.com/watch?v=He-GN_4MAY4&feature=youtu.be
B4: Week 1 3x5 | K4: Week 2 3x3 | S4: Week 3 5/3/1 | Y4: Week 4 Deload
A5: Day 1 | B5: Reps | C5: Weight | D5: Rep Goal | E5: 1RM Goal | F5: Best Reps Done | G5: 1RM | I5: Day 1 | J5: Reps | K5: Weight | L5: Rep Goal | M5: 1RM Goal | N5: Best Reps Done | O5: 1RM | Q5: Day 1 | R5: Reps | S5: Weight | T5: Rep Goal | U5: 1RM Goal | V5: Best Reps Done | W5: 1RM
A6: Pull Ups | B6: 3x6-8 | C6: 90 | D6: =IF('Start-Options'!D11="","",ROUND((37-36*C6/('Start-Options'!F11+'Start-Options'!F36)),0)) -> 5 | E6: =IF('Start-Options'!D11="","",MROUND(C6*36/(37-D6),'Start-Options'!$B$38)) -> 102.5 | F6: 8 | G6: =IF(F6="","",MROUND(36*C6/(37-F6),'Start-Options'!$B$38)) -> 112.5 | I6: Pull Ups | J6: 3x6-8 | K6: 90 | Q6: Pull Ups | R6: 3x6-8
A7: Dips | B7: 5x8 | C7: 90 | D7: =IF('Start-Options'!D11="","",ROUND((37-36*C7/('Start-Options'!F11+'Start-Options'!F35)),0)) -> 5 | E7: =IF('Start-Options'!D11="","",MROUND(C7*36/(37-D7),'Start-Options'!$B$38)) -> 102.5 | F7: 8 | G7: =IF(F7="","",MROUND(36*C7/(37-F7),'Start-Options'!$B$38)) -> 112.5 | I7: Dips | J7: 5x8 | K7: 90 | Q7: Dips | R7: 5x8
A8: Barbell Row | B8: 5x10 | C8: =IF('Start-Options'!D12="","",MROUND('Start-Options'!F12*0.75,'Start-Options'!$B$38)) -> 37.5 | D8: =IF('Start-Options'!D12="","",ROUND((37-36*C8/('Start-Options'!F12+'Start-Options'!F36)),0)) -> 11 | E8: =IF('Start-Options'!D12="","",MROUND(C8*36/(37-D8),'Start-Options'!$B$38)) -> 52.5 | F8: 12 | G8: =IF(F8="","",MROUND(36*C8/(37-F8),'Start-Options'!$B$38)) -> 55 | I8: Barbell Row | J8: 5x10 | K8: =IF('Start-Options'!D12="","",MROUND('Start-Options'!D12*0.75,'Start-Options'!$B$38)) -> 7.5 | Q8: Barbell Row | R8: 5x10
A9: BB Curl | B9: 5x10 | C9: =IF('Start-Options'!D14="","",MROUND('Start-Options'!F14*0.75,'Start-Options'!$B$38)) -> 20 | D9: =IF('Start-Options'!D14="","",ROUND((37-36*C9/('Start-Options'!F14+'Start-Options'!F36)),0)) -> 11 | E9: =IF('Start-Options'!D14="","",MROUND(C9*36/(37-D9),'Start-Options'!$B$38)) -> 27.5 | F9: 9 | G9: =IF(F9="","",MROUND(36*C9/(37-F9),'Start-Options'!$B$38)) -> 25 | I9: BB Curl | J9: 5x10 | K9: =IF('Start-Options'!D14="","",MROUND('Start-Options'!F14*0.75,'Start-Options'!$B$38)) -> 20 | Q9: BB Curl | R9: 5x10
A10: BB Rear Delt Row | B10: 3x10 | C10: 30 | D10: =IF('Start-Options'!D15="","",ROUND((37-36*C10/('Start-Options'!F15+'Start-Options'!F34)),0)) -> 8 | E10: =IF('Start-Options'!D15="","",MROUND(C10*36/(37-D10),'Start-Options'!$B$38)) -> 37.5 | F10: 10 | G10: =IF(F10="","",MROUND(36*C10/(37-F10),'Start-Options'!$B$38)) -> 40 | I10: BB Rear Delt Row | J10: 3x10 | K10: 30 | Q10: BB Rear Delt Row | R10: 3x10
A11: Lateral Raise | B11: 3x10 | C11: 10 | D11: =IF('Start-Options'!D16="","",ROUND((37-36*C11/('Start-Options'!F16+'Start-Options'!F35)),0)) -> 16 | E11: =IF('Start-Options'!D16="","",MROUND(C11*36/(37-D11),'Start-Options'!$B$38)) -> 17.5 | F11: 12 | G11: =IF(F11="","",MROUND(36*C11/(37-F11),'Start-Options'!$B$38)) -> 15 | I11: Lateral Raise | J11: 3x10 | K11: 10 | Q11: Lateral Raise | R11: 3x10
A12: Day 2 | B12: Reps | C12: Weight | D12: Rep Goal | E12: 1RM Goal | F12: Best Reps Done | G12: 1RM | I12: Day 2 | J12: Reps | Q12: Day 2 | R12: Reps
A13: RDL | B13: 5x12 | C13: =IF('Start-Options'!D18="","",MROUND('Start-Options'!F18*0.75,'Start-Options'!$B$38)) -> 42.5 | D13: =IF('Start-Options'!D18="","",ROUND((37-36*C13/('Start-Options'!F18+'Start-Options'!$F$36)),0)) -> 10 | E13: =IF('Start-Options'!D18="","",MROUND(C13*36/(37-D13),'Start-Options'!$B$38)) -> 57.5 | G13: =IF(F13="","",MROUND(36*C13/(37-F13),'Start-Options'!$B$38)) | I13: RDL | J13: 5x12 | Q13: RDL | R13: 5x12
A14: Stiff Leg Deadlift | B14: 5x10 | C14: =IF('Start-Options'!D19="","",MROUND('Start-Options'!F19*0.75,'Start-Options'!$B$38)) -> 27.5 | D14: =IF('Start-Options'!D19="","",ROUND((37-36*C14/('Start-Options'!F19+'Start-Options'!$F$36)),0)) -> 11 | E14: =IF('Start-Options'!D19="","",MROUND(C14*36/(37-D14),'Start-Options'!$B$38)) -> 37.5 | G14: =IF(F14="","",MROUND(36*C14/(37-F14),'Start-Options'!$B$38)) | I14: Stiff Leg Deadlift | J14: 5x10 | Q14: Stiff Leg Deadlift | R14: 5x10
A15: Hanging Leg Raise | B15: 5x15 | C15: 90 | D15: =IF('Start-Options'!D20="","",ROUND((37-36*C15/('Start-Options'!F20+'Start-Options'!$F$36)),0)) -> 5 | E15: =IF('Start-Options'!D20="","",MROUND(C15*36/(37-D15),'Start-Options'!$B$38)) -> 102.5 | F15: 22 | G15: =IF(F15="","",MROUND(36*C15/(37-F15),'Start-Options'!$B$38)) -> 215 | I15: Hanging Leg Raise | J15: 5x15 | Q15: Hanging Leg Raise | R15: 5x15
A16: Day 3 | B16: Reps | C16: Weight | D16: Rep Goal | E16: 1RM Goal | F16: Best Reps Done | G16: 1RM | I16: Day 3 | J16: Reps | Q16: Day 3 | R16: Reps
A17: Barbell Row | B17: 5x10 | C17: =IF('Start-Options'!D12="","",MROUND('Start-Options'!F12*0.75,'Start-Options'!$B$38)) -> 37.5 | D17: =IF(G8="","",IF(G8<'Start-Options'!F12,ROUND((37-36*C17/('Start-Options'!F12+'Start-Options'!$F$36)),0),ROUND((37-36*C17/(G8+'Start-Options'!$F$36)),0))) -> 14 | E17: =IF(D17="","",MROUND(C17*36/(37-D17),'Start-Options'!B38)) -> 57.5 | F17: 3 | G17: =IF(F17="","",MROUND(36*C17/(37-F17),'Start-Options'!$B$38)) -> 40 | I17: Barbell Row | J17: 5x10 | Q17: Barbell Row | R17: 5x10
A18: Chin Ups | B18: 3x6-8 | C18: 90 | D18: =IF('Start-Options'!D22="","",ROUND((37-36*C18/('Start-Options'!F22+'Start-Options'!$F$36)),0)) -> 5 | E18: =IF('Start-Options'!D22="","",MROUND(C18*36/(37-D18),'Start-Options'!$B$38)) -> 102.5 | G18: =IF(F18="","",MROUND(36*C18/(37-F18),'Start-Options'!$B$38)) | I18: Chin Ups | J18: 3x6-8 | Q18: Chin Ups | R18: 3x6-8
A19: Incline Bench | B19: 5x15 | C19: =IF('Start-Options'!D23="","",MROUND('Start-Options'!F23*0.75,'Start-Options'!$B$38)) -> 42.5 | D19: =IF('Start-Options'!D23="","",ROUND((37-36*C19/('Start-Options'!F23+'Start-Options'!$F$36)),0)) -> 10 | E19: =IF(D19="","",MROUND(C19*36/(37-D19),'Start-Options'!$B$38)) -> 57.5 | G19: =IF(F19="","",MROUND(36*C19/(37-F19),'Start-Options'!$B$38)) | I19: Incline Bench | J19: 5x15 | Q19: Incline Bench | R19: 5x15
A20: Hammer Curl | B20: 5x10 | C20: =IF('Start-Options'!D24="","",MROUND('Start-Options'!F24*0.75,'Start-Options'!$B$38)) -> 27.5 | D20: =IF('Start-Options'!D24="","",ROUND((37-36*C20/('Start-Options'!F24+'Start-Options'!$F$36)),0)) -> 11 | E20: =IF(D20="","",MROUND(C20*36/(37-D20),'Start-Options'!$B$38)) -> 37.5 | G20: =IF(F20="","",MROUND(36*C20/(37-F20),'Start-Options'!$B$38)) | I20: Hammer Curl | J20: 5x10 | Q20: Hammer Curl | R20: 5x10
A21: BB Overhead Triceps Extension | B21: 5x10 | C21: =IF('Start-Options'!D25="","",MROUND('Start-Options'!F25*0.75,'Start-Options'!$B$38)) -> 12.5 | D21: =IF('Start-Options'!D25="","",ROUND((37-36*C21/('Start-Options'!F25+'Start-Options'!$F$36)),0)) -> 11 | E21: =IF(D21="","",MROUND(C21*36/(37-D21),'Start-Options'!$B$38)) -> 17.5 | G21: =IF(F21="","",MROUND(36*C21/(37-F21),'Start-Options'!$B$38)) | I21: BB Overhead Triceps Extension | J21: 5x10 | Q21: BB Overhead Triceps Extension | R21: 5x10
A22: BB Rear Delt Row | B22: 3x10 | C22: =IF('Start-Options'!D15="","",MROUND('Start-Options'!F15*0.75,'Start-Options'!$B$38)) -> 27.5 | D22: =IF(G10="","",IF(G10<'Start-Options'!F17,ROUND((37-36*C22/('Start-Options'!F17+'Start-Options'!$F$36)),0),ROUND((37-36*C22/(G10+'Start-Options'!$F$36)),0))) -> 14 | E22: =IF(D22="","",MROUND(C22*36/(37-D22),'Start-Options'!$B$38)) -> 42.5 | G22: =IF(F22="","",MROUND(36*C22/(37-F22),'Start-Options'!$B$38)) | I22: BB Rear Delt Row | J22: 3x10 | Q22: BB Rear Delt Row | R22: 3x10
A23: Day 4 | B23: Reps | C23: Weight | D23: Rep Goal | E23: 1RM Goal | F23: Best Reps Done | G23: 1RM | I23: Day 4 | J23: Reps | Q23: Day 4 | R23: Reps
A24: Barbell Row | B24: 5x10 | C24: =IF('Start-Options'!D12="","",MROUND('Start-Options'!F12*0.75,'Start-Options'!$B$38)) -> 37.5 | D24: =IF(G17="","",IF(G17<'Start-Options'!F19,ROUND((37-36*C24/('Start-Options'!F19+'Start-Options'!$F$36)),0),ROUND((37-36*C24/(G17+'Start-Options'!$F$36)),0))) -> 5 | E24: =IF(D24="","",MROUND(C24*36/(37-D24),'Start-Options'!$B$38)) -> 42.5 | G24: =IF(F24="","",MROUND(36*C24/(37-F24),'Start-Options'!$B$38)) | I24: Barbell Row | J24: 5x10 | Q24: Barbell Row | R24: 5x10
A25: Front Squat | B25: 5x10 | C25: =IF('Start-Options'!D27="","",MROUND('Start-Options'!F27*0.75,'Start-Options'!$B$38)) -> 27.5 | D25: =IF('Start-Options'!D27="","",ROUND((37-36*C25/('Start-Options'!F27+'Start-Options'!$F$36)),0)) -> 11 | E25: =IF(D25="","",MROUND(C25*36/(37-D25),'Start-Options'!$B$38)) -> 37.5 | G25: =IF(F25="","",MROUND(36*C25/(37-F25),'Start-Options'!$B$38)) | I25: Front Squat | J25: 5x10 | Q25: Front Squat | R25: 5x10
A26: Good Mornings | B26: 5x10 | C26: =IF('Start-Options'!D28="","",MROUND('Start-Options'!F28*0.75,'Start-Options'!$B$38)) -> 12.5 | D26: =IF('Start-Options'!D28="","",ROUND((37-36*C26/('Start-Options'!F28+'Start-Options'!$F$36)),0)) -> 11 | E26: =IF(D26="","",MROUND(C26*36/(37-D26),'Start-Options'!$B$38)) -> 17.5 | G26: =IF(F26="","",MROUND(36*C26/(37-F26),'Start-Options'!$B$38)) | I26: Good Mornings | J26: 5x10 | Q26: Good Mornings | R26: 5x10
A27: Barbell Hip Thrust | B27: 5x15 | C27: =IF('Start-Options'!D29="","",MROUND('Start-Options'!F29*0.75,'Start-Options'!$B$38)) -> 12.5 | D27: =IF('Start-Options'!D29="","",ROUND((37-36*C27/('Start-Options'!F29+'Start-Options'!$F$36)),0)) -> 11 | E27: =IF(D27="","",MROUND(C27*36/(37-D27),'Start-Options'!$B$38)) -> 17.5 | G27: =IF(F27="","",MROUND(36*C27/(37-F27),'Start-Options'!$B$38)) | I27: Barbell Hip Thrust | J27: 5x15 | Q27: Barbell Hip Thrust | R27: 5x15
A28: Hanging Leg Raise | B28: 5x15 | C28: 90 | D28: =IF(G15="","",IF(G15<'Start-Options'!F23,ROUND((37-36*C28/('Start-Options'!F23+'Start-Options'!$F$36)),0),ROUND((37-36*C28/(G15+'Start-Options'!$F$36)),0))) -> 22 | E28: =IF(D28="","",MROUND(C28*36/(37-D28),'Start-Options'!$B$38)) -> 215 | G28: =IF(F28="","",MROUND(36*C28/(37-F28),'Start-Options'!$B$38)) | I28: Hanging Leg Raise | J28: 5x15 | Q28: Hanging Leg Raise | R28: 5x15

Sheet 531 Progress Tracker
H1: 5/3/1 Progress Tracker | M1: v3.0F
C2: ONLY Compatible with 5/3/1
H4: Highest Estimated 1RM to Date | M4: 5/3/1 Program
H5: Military | I5: Deadlift | J5: Bench | K5: Squat | M5: Accessory Planner
H6: =IF(MAX(X11:X49)=0,"",MAX(X11:X49)) -> 67.5 | I6: =IF(MAX(Y11:Y49)=0,"",MAX(Y11:Y49)) -> 152.5 | J6: =IF(MAX(Z11:Z49)=0,"",MAX(Z11:Z49)) -> 85 | K6: =IF(MAX(AA11:AA49)=0,"",MAX(AA11:AA49)) -> 107.5 | M6: Start/Options | X6: Military | Y6: Deadlift | Z6: Bench | AA6: Squat
V7: Nästa nivå: | X7: =IF(X9="Beginner!",'Nivåer'!D4,IF(X9="Novice!",'Nivåer'!D5,IF(X9="Intermediate!",'Nivåer'!D6,IF(X9="Advanced!",'Nivåer'!D7,IF(X9="Elite!",'Nivåer'!D8,""))))) -> 71 | Y7: =IF(Y9="Beginner!",'Nivåer'!F4,IF(Y9="Novice!",'Nivåer'!F5,IF(Y9="Intermediate!",'Nivåer'!F6,IF(Y9="Advanced!",'Nivåer'!F7,IF(Y9="Elite!",'Nivåer'!F8,""))))) -> 161 | Z7: =IF(Z9="Beginner!",'Nivåer'!B4,IF(Z9="Novice!",'Nivåer'!B5,IF(Z9="Intermediate!",'Nivåer'!B6,IF(Z9="Advanced!",'Nivåer'!B7,IF(Z9="Elite!",'Nivåer'!B8,""))))) -> 106 | AA7: =IF(AA9="Beginner!",'Nivåer'!H4,IF(AA9="Novice!",'Nivåer'!H5,IF(AA9="Intermediate!",'Nivåer'!H6,IF(AA9="Advanced!",'Nivåer'!H7,IF(AA9="Elite!",'Nivåer'!H8,""))))) -> 139
V8: Kilon kvar | X8: =X7-H6 -> 3.5 | Y8: =Y7-I6 -> 8.5 | Z8: =Z7-J6 -> 21 | AA8: =AA7-K6 -> 31.5
